[2023-11-09T00:44:08.461+0000] {taskinstance.py:1083} INFO - Dependencies all met for <TaskInstance: user_processing.extract_user scheduled__2023-11-08T00:00:00+00:00 [queued]>
[2023-11-09T00:44:08.466+0000] {taskinstance.py:1083} INFO - Dependencies all met for <TaskInstance: user_processing.extract_user scheduled__2023-11-08T00:00:00+00:00 [queued]>
[2023-11-09T00:44:08.467+0000] {taskinstance.py:1279} INFO - 
--------------------------------------------------------------------------------
[2023-11-09T00:44:08.467+0000] {taskinstance.py:1280} INFO - Starting attempt 1 of 1
[2023-11-09T00:44:08.467+0000] {taskinstance.py:1281} INFO - 
--------------------------------------------------------------------------------
[2023-11-09T00:44:08.473+0000] {taskinstance.py:1300} INFO - Executing <Task(SimpleHttpOperator): extract_user> on 2023-11-08 00:00:00+00:00
[2023-11-09T00:44:08.477+0000] {standard_task_runner.py:55} INFO - Started process 18437 to run task
[2023-11-09T00:44:08.479+0000] {standard_task_runner.py:82} INFO - Running: ['***', 'tasks', 'run', 'user_processing', 'extract_user', 'scheduled__2023-11-08T00:00:00+00:00', '--job-id', '64', '--raw', '--subdir', 'DAGS_FOLDER/user_processing.py', '--cfg-path', '/tmp/tmp3da6vm8n']
[2023-11-09T00:44:08.480+0000] {standard_task_runner.py:83} INFO - Job 64: Subtask extract_user
[2023-11-09T00:44:08.510+0000] {task_command.py:388} INFO - Running <TaskInstance: user_processing.extract_user scheduled__2023-11-08T00:00:00+00:00 [running]> on host cff42873677f
[2023-11-09T00:44:08.540+0000] {taskinstance.py:1509} INFO - Exporting the following env vars:
AIRFLOW_CTX_DAG_OWNER=***
AIRFLOW_CTX_DAG_ID=user_processing
AIRFLOW_CTX_TASK_ID=extract_user
AIRFLOW_CTX_EXECUTION_DATE=2023-11-08T00:00:00+00:00
AIRFLOW_CTX_TRY_NUMBER=1
AIRFLOW_CTX_DAG_RUN_ID=scheduled__2023-11-08T00:00:00+00:00
[2023-11-09T00:44:08.541+0000] {http.py:123} INFO - Calling HTTP method
[2023-11-09T00:44:08.545+0000] {base.py:73} INFO - Using connection ID 'user_api' for task execution.
[2023-11-09T00:44:23.756+0000] {http.py:208} WARNING - ('Connection aborted.', RemoteDisconnected('Remote end closed connection without response')) Tenacity will retry to execute the operation
[2023-11-09T00:44:23.760+0000] {taskinstance.py:1768} ERROR - Task failed with exception
Traceback (most recent call last):
  File "/home/airflow/.local/lib/python3.7/site-packages/urllib3/connectionpool.py", line 710, in urlopen
    chunked=chunked,
  File "/home/airflow/.local/lib/python3.7/site-packages/urllib3/connectionpool.py", line 449, in _make_request
    six.raise_from(e, None)
  File "<string>", line 3, in raise_from
  File "/home/airflow/.local/lib/python3.7/site-packages/urllib3/connectionpool.py", line 444, in _make_request
    httplib_response = conn.getresponse()
  File "/usr/local/lib/python3.7/http/client.py", line 1373, in getresponse
    response.begin()
  File "/usr/local/lib/python3.7/http/client.py", line 319, in begin
    version, status, reason = self._read_status()
  File "/usr/local/lib/python3.7/http/client.py", line 288, in _read_status
    raise RemoteDisconnected("Remote end closed connection without"
http.client.RemoteDisconnected: Remote end closed connection without response

During handling of the above exception, another exception occurred:

Traceback (most recent call last):
  File "/home/airflow/.local/lib/python3.7/site-packages/requests/adapters.py", line 499, in send
    timeout=timeout,
  File "/home/airflow/.local/lib/python3.7/site-packages/urllib3/connectionpool.py", line 788, in urlopen
    method, url, error=e, _pool=self, _stacktrace=sys.exc_info()[2]
  File "/home/airflow/.local/lib/python3.7/site-packages/urllib3/util/retry.py", line 550, in increment
    raise six.reraise(type(error), error, _stacktrace)
  File "/home/airflow/.local/lib/python3.7/site-packages/urllib3/packages/six.py", line 769, in reraise
    raise value.with_traceback(tb)
  File "/home/airflow/.local/lib/python3.7/site-packages/urllib3/connectionpool.py", line 710, in urlopen
    chunked=chunked,
  File "/home/airflow/.local/lib/python3.7/site-packages/urllib3/connectionpool.py", line 449, in _make_request
    six.raise_from(e, None)
  File "<string>", line 3, in raise_from
  File "/home/airflow/.local/lib/python3.7/site-packages/urllib3/connectionpool.py", line 444, in _make_request
    httplib_response = conn.getresponse()
  File "/usr/local/lib/python3.7/http/client.py", line 1373, in getresponse
    response.begin()
  File "/usr/local/lib/python3.7/http/client.py", line 319, in begin
    version, status, reason = self._read_status()
  File "/usr/local/lib/python3.7/http/client.py", line 288, in _read_status
    raise RemoteDisconnected("Remote end closed connection without"
urllib3.exceptions.ProtocolError: ('Connection aborted.', RemoteDisconnected('Remote end closed connection without response'))

During handling of the above exception, another exception occurred:

Traceback (most recent call last):
  File "/home/airflow/.local/lib/python3.7/site-packages/airflow/providers/http/operators/http.py", line 125, in execute
    response = http.run(self.endpoint, self.data, self.headers, self.extra_options)
  File "/home/airflow/.local/lib/python3.7/site-packages/airflow/providers/http/hooks/http.py", line 151, in run
    return self.run_and_check(session, prepped_request, extra_options)
  File "/home/airflow/.local/lib/python3.7/site-packages/airflow/providers/http/hooks/http.py", line 209, in run_and_check
    raise ex
  File "/home/airflow/.local/lib/python3.7/site-packages/airflow/providers/http/hooks/http.py", line 201, in run_and_check
    response = session.send(prepped_request, **send_kwargs)
  File "/home/airflow/.local/lib/python3.7/site-packages/requests/sessions.py", line 701, in send
    r = adapter.send(request, **kwargs)
  File "/home/airflow/.local/lib/python3.7/site-packages/requests/adapters.py", line 547, in send
    raise ConnectionError(err, request=request)
requests.exceptions.ConnectionError: ('Connection aborted.', RemoteDisconnected('Remote end closed connection without response'))
[2023-11-09T00:44:23.778+0000] {taskinstance.py:1323} INFO - Marking task as FAILED. dag_id=user_processing, task_id=extract_user, execution_date=20231108T000000, start_date=20231109T004408, end_date=20231109T004423
[2023-11-09T00:44:23.795+0000] {standard_task_runner.py:105} ERROR - Failed to execute job 64 for task extract_user (('Connection aborted.', RemoteDisconnected('Remote end closed connection without response')); 18437)
[2023-11-09T00:44:23.816+0000] {local_task_job.py:208} INFO - Task exited with return code 1
[2023-11-09T00:44:23.837+0000] {taskinstance.py:2578} INFO - 0 downstream tasks scheduled from follow-on schedule check
